Workbook

Sheet Overview
A1: TripTiles Catalogue Snapshot
A2: 10 May 2026 · Supabase project hjbbojypllltfjfuojzn · read-only audit
A4: Catalogue totals
A5: Regions | B5: =COUNTA(Regions!A2:A1000) -> 43
A6: Parks | B6: =COUNTA(Parks!A2:A1000) -> 351
A7: Attractions | B7: =COUNTA(Attractions!A2:A1000) -> 100
A8: Skip-line mappings | B8: =COUNTA('Skip-Line Map'!A2:A1000) -> 46
A11: Regions by data quality tier
A12: Tier | B12: Count | C12: Of which overstated
A13: Deep | B13: =COUNTIF(Regions!L2:L1000,"deep") -> 2 | C13: =COUNTIFS(Regions!L2:L1000,"deep",Regions!U2:U1000,"*tier_overstated*") -> 0
A14: Standard | B14: =COUNTIF(Regions!L2:L1000,"standard") -> 7 | C14: =COUNTIFS(Regions!L2:L1000,"standard",Regions!U2:U1000,"*tier_overstated*") -> 4
A15: Light | B15: =COUNTIF(Regions!L2:L1000,"light") -> 34
A18: Universal park-level data status
A19: Field | B19: Parks populated | C19: Of total
A20: Latitude/longitude | B20: =COUNTA(Parks!G2:G1000) -> 0 | C20: =COUNTA(Parks!A2:A1000) -> 351
A21: Official URL | B21: =COUNTIFS(Parks!I2:I1000,"<>") -> 0 | C21: =COUNTA(Parks!A2:A1000) -> 351
A22: Hours known | B22: =COUNTIF(Parks!L2:L1000,TRUE()) -> 0 | C22: =COUNTA(Parks!A2:A1000) -> 351
A23: Country | B23: =COUNTIFS(Parks!F2:F1000,"<>") -> 0 | C23: =COUNTA(Parks!A2:A1000) -> 351
A24: Icon | B24: =COUNTIFS(Parks!C2:C1000,"<>") -> 8 | C24: =COUNTA(Parks!A2:A1000) -> 351
A27: Gap flag legend
A28: Entity | B28: Flag | C28: Meaning | D28: Fix
A29: Region | B29: description_too_short | C29: description_chars < 20 | D29: Write a 1–2 sentence region intro
A30: Region | B30: no_skip_line_systems | C30: No row in region_skip_line_systems (not even 'none') | D30: Add a row to the join table
A31: Region | B31: tier_overstated_no_attractions | C31: Tier is 'standard' or 'deep' but attractions_count = 0 | D31: Retag to 'light' (1-min UPDATE) or fill with attractions
A32: Region | B32: no_parks_with_hours | C32: Every park has hours_known = false | D32: Source park hours, set on parks
A33: Region | B33: no_parks_with_coords | C33: Every park has latitude IS NULL | D33: Source coords, set on parks
A34: Region | B34: no_parks_with_url | C34: No park has official_url populated | D34: Source official URLs, set on parks
A35: Park | B35: no_icon | C35: icon IS NULL OR '' | D35: Add an emoji (cosmetic)
A36: Park | B36: no_country | C36: country IS NULL OR '' | D36: Set country
A37: Park | B37: no_coords | C37: latitude IS NULL | D37: Source lat/lng
A38: Park | B38: no_official_url | C38: official_url IS NULL OR '' | D38: Source URL
A39: Park | B39: no_hours | C39: hours_known = false | D39: Source opening hours, set hours_known = true
... A46: Attraction | B46: no_official_url | C46: official_url IS NULL OR '' | D46: Source URL

Sheet Regions
A1: id | B1: name | C1: short_name | D1: country | E1: country_code | F1: continent | G1: flag_emoji | H1: is_active | I1: is_featured | J1: has_disney | K1: has_universal | L1: data_quality_tier | M1: sort_order | N1: description_chars | O1: parks_count | P1: parks_with_hours | Q1: parks_with_coords | R1: parks_with_url | S1: attractions_count | T1: skip_line_systems | U1: parity_gaps
A2: orlando | B2: Orlando, Florida | C2: Orlando | D2: United States | E2: US | F2: North America | G2: 🇺🇸 | H2: =TRUE() -> TRUE | I2: =TRUE() -> TRUE | J2: =TRUE() -> TRUE | K2: =TRUE() -> TRUE | L2: deep | M2: 10 | N2: 55 | O2: 44 | P2: 0 | Q2: 0 | R2: 0 | S2: 60 | T2: 2 | U2: no_parks_with_hours|no_parks_with_coords|no_parks_with_url
A3: cali | B3: Anaheim & California | C3: California | D3: United States | E3: US | F3: North America | G3: 🇺🇸 | H3: =TRUE() -> TRUE | I3: =TRUE() -> TRUE | J3: =TRUE() -> TRUE | K3: =TRUE() -> TRUE | L3: standard | M3: 11 | N3: 58 | O3: 35 | P3: 0 | Q3: 0 | R3: 0 | S3: 18 | T3: 2 | U3: no_parks_with_hours|no_parks_with_coords|no_parks_with_url
A4: lasvegas | B4: Las Vegas | C4: Las Vegas | D4: United States | E4: US | F4: North America | G4: 🇺🇸 | H4: =TRUE() -> TRUE | I4: =FALSE() -> FALSE | J4: =FALSE() -> FALSE | K4: =FALSE() -> FALSE | L4: light | M4: 12 | N4: 35 | O4: 25 | P4: 0 | Q4: 0 | R4: 0 | S4: 0 | T4: 1 | U4: no_parks_with_hours|no_parks_with_coords|no_parks_with_url
A5: toronto | B5: Toronto | C5: Toronto | D5: Canada | E5: CA | F5: North America | G5: 🇨🇦 | H5: =TRUE() -> TRUE | I5: =FALSE() -> FALSE | J5: =FALSE() -> FALSE | K5: =FALSE() -> FALSE | L5: light | M5: 13 | N5: 43 | O5: 26 | P5: 0 | Q5: 0 | R5: 0 | S5: 0 | T5: 1 | U5: no_parks_with_hours|no_parks_with_coords|no_parks_with_url
A6: mexico | B6: Mexico | C6: Mexico | D6: Mexico | E6: MX | F6: North America | G6: 🇲🇽 | H6: =TRUE() -> TRUE | I6: =FALSE() -> FALSE | J6: =FALSE() -> FALSE | K6: =FALSE() -> FALSE | L6: light | M6: 14 | N6: 41 | O6: 28 | P6: 0 | Q6: 0 | R6: 0 | S6: 0 | T6: 1 | U6: no_parks_with_hours|no_parks_with_coords|no_parks_with_url
A7: miami | B7: Miami & South Florida | C7: Miami | D7: United States | E7: US | F7: North America | G7: 🇺🇸 | H7: =TRUE() -> TRUE | I7: =TRUE() -> TRUE | J7: =FALSE() -> FALSE | K7: =FALSE() -> FALSE | L7: light | M7: 15 | N7: 60 | O7: 63 | P7: 0 | Q7: 0 | R7: 0 | S7: 0 | T7: 1 | U7: no_parks_with_hours|no_parks_with_coords|no_parks_with_url
A8: florida_combo | B8: Florida Combo (Orlando + Miami) | C8: FL Combo | D8: United States | E8: US | F8: North America | G8: 🇺🇸 | H8: =TRUE() -> TRUE | I8: =TRUE() -> TRUE | J8: =TRUE() -> TRUE | K8: =TRUE() -> TRUE | L8: deep | M8: 16 | N8: 61 | O8: 85 | P8: 0 | Q8: 0 | R8: 0 | S8: 60 | T8: 2 | U8: no_parks_with_hours|no_parks_with_coords|no_parks_with_url
A9: paris | B9: Paris | C9: Paris | D9: France | E9: FR | F9: Europe | G9: 🇫🇷 | H9: =TRUE() -> TRUE | I9: =TRUE() -> TRUE | J9: =TRUE() -> TRUE | K9: =FALSE() -> FALSE | L9: standard | M9: 20 | N9: 53 | O9: 35 | P9: 0 | Q9: 0 | R9: 0 | S9: 15 | T9: 1 | U9: no_parks_with_hours|no_parks_with_coords|no_parks_with_url
A10: uk | B10: United Kingdom | C10: UK | D10: United Kingdom | E10: GB | F10: Europe | G10: 🇬🇧 | H10: =TRUE() -> TRUE | I10: =TRUE() -> TRUE | J10: =FALSE() -> FALSE | K10: =FALSE() -> FALSE | L10: light | M10: 21 | N10: 53 | O10: 33 | P10: 0 | Q10: 0 | R10: 0 | S10: 0 | T10: 1 | U10: no_parks_with_hours|no_parks_with_coords|no_parks_with_url
A11: germany | B11: Germany | C11: Germany | D11: Germany | E11: DE | F11: Europe | G11: 🇩🇪 | H11: =TRUE() -> TRUE | I11: =TRUE() -> TRUE | J11: =FALSE() -> FALSE | K11: =FALSE() -> FALSE | L11: light | M11: 22 | N11: 48 | O11: 30 | P11: 0 | Q11: 0 | R11: 0 | S11: 0 | T11: 1 | U11: no_parks_with_hours|no_parks_with_coords|no_parks_with_url
A12: spain | B12: Costa Daurada, Spain | C12: Spain | D12: Spain | E12: ES | F12: Europe | G12: 🇪🇸 | H12: =TRUE() -> TRUE | I12: =TRUE() -> TRUE | J12: =FALSE() -> FALSE | K12: =FALSE() -> FALSE | L12: light | M12: 23 | N12: 47 | O12: 30 | P12: 0 | Q12: 0 | R12: 0 | S12: 0 | T12: 1 | U12: no_parks_with_hours|no_parks_with_coords|no_parks_with_url
A13: netherlands | B13: Netherlands | C13: Netherlands | D13: Netherlands | E13: NL | F13: Europe | G13: 🇳🇱 | H13: =TRUE() -> TRUE | I13: =FALSE() -> FALSE | J13: =FALSE() -> FALSE | K13: =FALSE() -> FALSE | L13: light | M13: 24 | N13: 38 | O13: 26 | P13: 0 | Q13: 0 | R13: 0 | S13: 0 | T13: 1 | U13: no_parks_with_hours|no_parks_with_coords|no_parks_with_url
A14: denmark | B14: Denmark | C14: Denmark | D14: Denmark | E14: DK | F14: Europe | G14: 🇩🇰 | H14: =TRUE() -> TRUE | I14: =FALSE() -> FALSE | J14: =FALSE() -> FALSE | K14: =FALSE() -> FALSE | L14: light | M14: 25 | N14: 47 | O14: 26 | P14: 0 | Q14: 0 | R14: 0 | S14: 0 | T14: 1 | U14: no_parks_with_hours|no_parks_with_coords|no_parks_with_url
A15: italy | B15: Italy | C15: Italy | D15: Italy | E15: IT | F15: Europe | G15: 🇮🇹 | H15: =TRUE() -> TRUE | I15: =FALSE() -> FALSE | J15: =FALSE() -> FALSE | K15: =FALSE() -> FALSE | L15: light | M15: 26 | N15: 44 | O15: 28 | P15: 0 | Q15: 0 | R15: 0 | S15: 0 | T15: 1 | U15: no_parks_with_hours|no_parks_with_coords|no_parks_with_url
A16: belgium | B16: Belgium | C16: Belgium | D16: Belgium | E16: BE | F16: Europe | G16: 🇧🇪 | H16: =TRUE() -> TRUE | I16: =FALSE() -> FALSE | J16: =FALSE() -> FALSE | K16: =FALSE() -> FALSE | L16: light | M16: 27 | N16: 29 | O16: 26 | P16: 0 | Q16: 0 | R16: 0 | S16: 0 | T16: 1 | U16: no_parks_with_hours|no_parks_with_coords|no_parks_with_url
A17: sweden | B17: Sweden | C17: Sweden | D17: Sweden | E17: SE | F17: Europe | G17: 🇸🇪 | H17: =TRUE() -> TRUE | I17: =FALSE() -> FALSE | J17: =FALSE() -> FALSE | K17: =FALSE() -> FALSE | L17: light | M17: 28 | N17: 23 | O17: 25 | P17: 0 | Q17: 0 | R17: 0 | S17: 0 | T17: 1 | U17: no_parks_with_hours|no_parks_with_coords|no_parks_with_url
A18: finland | B18: Finland | C18: Finland | D18: Finland | E18: FI | F18: Europe | G18: 🇫🇮 | H18: =TRUE() -> TRUE | I18: =FALSE() -> FALSE | J18: =FALSE() -> FALSE | K18: =FALSE() -> FALSE | L18: light | M18: 29 | N18: 23 | O18: 25 | P18: 0 | Q18: 0 | R18: 0 | S18: 0 | T18: 1 | U18: no_parks_with_hours|no_parks_with_coords|no_parks_with_url
A19: tokyo | B19: Tokyo | C19: Tokyo | D19: Japan | E19: JP | F19: Asia | G19: 🇯🇵 | H19: =TRUE() -> TRUE | I19: =TRUE() -> TRUE | J19: =TRUE() -> TRUE | K19: =FALSE() -> FALSE | L19: standard | M19: 30 | N19: 46 | O19: 40 | P19: 0 | Q19: 0 | R19: 0 | S19: 0 | T19: 1 | U19: tier_overstated_no_attractions|no_parks_with_hours|no_parks_with_coords|no_parks_with_url
A20: osaka | B20: Osaka & Kansai | C20: Osaka | D20: Japan | E20: JP | F20: Asia | G20: 🇯🇵 | H20: =TRUE() -> TRUE | I20: =FALSE() -> FALSE | J20: =FALSE() -> FALSE | K20: =TRUE() -> TRUE | L20: standard | M20: 31 | N20: 45 | O20: 26 | P20: 0 | Q20: 0 | R20: 0 | S20: 0 | T20: 1 | U20: tier_overstated_no_attractions|no_parks_with_hours|no_parks_with_coords|no_parks_with_url
A21: shanghai | B21: Shanghai | C21: Shanghai | D21: China | E21: CN | F21: Asia | G21: 🇨🇳 | H21: =TRUE() -> TRUE | I21: =TRUE() -> TRUE | J21: =TRUE() -> TRUE | K21: =FALSE() -> FALSE | L21: standard | M21: 32 | N21: 34 | O21: 30 | P21: 0 | Q21: 0 | R21: 0 | S21: 0 | T21: 1 | U21: tier_overstated_no_attractions|no_parks_with_hours|no_parks_with_coords|no_parks_with_url
A22: hongkong | B22: Hong Kong | C22: Hong Kong | D22: Hong Kong | E22: HK | F22: Asia | G22: 🇭🇰 | H22: =TRUE() -> TRUE | I22: =TRUE() -> TRUE | J22: =TRUE() -> TRUE | K22: =FALSE() -> FALSE | L22: standard | M22: 33 | N22: 35 | O22: 27 | P22: 0 | Q22: 0 | R22: 0 | S22: 7 | T22: 1 | U22: no_parks_with_hours|no_parks_with_coords|no_parks_with_url
A23: singapore | B23: Singapore | C23: Singapore | D23: Singapore | E23: SG | F23: Asia | G23: 🇸🇬 | H23: =TRUE() -> TRUE | I23: =TRUE() -> TRUE | J23: =FALSE() -> FALSE | K23: =TRUE() -> TRUE | L23: standard | M23: 34 | N23: 39 | O23: 29 | P23: 0 | Q23: 0 | R23: 0 | S23: 0 | T23: 1 | U23: tier_overstated_no_attractions|no_parks_with_hours|no_parks_with_coords|no_parks_with_url
A24: seoul | B24: Seoul | C24: Seoul | D24: South Korea | E24: KR | F24: Asia | G24: 🇰🇷 | H24: =TRUE() -> TRUE | I24: =FALSE() -> FALSE | J24: =FALSE() -> FALSE | K24: =FALSE() -> FALSE | L24: light | M24: 35 | N24: 24 | O24: 26 | P24: 0 | Q24: 0 | R24: 0 | S24: 0 | T24: 1 | U24: no_parks_with_hours|no_parks_with_coords|no_parks_with_url
A25: uae | B25: Dubai & Abu Dhabi | C25: UAE | D25: United Arab Emirates | E25: AE | F25: Middle East | G25: 🇦🇪 | H25: =TRUE() -> TRUE | I25: =TRUE() -> TRUE | J25: =FALSE() -> FALSE | K25: =FALSE() -> FALSE | L25: light | M25: 40 | N25: 66 | O25: 36 | P25: 0 | Q25: 0 | R25: 0 | S25: 0 | T25: 1 | U25: no_parks_with_hours|no_parks_with_coords|no_parks_with_url
A26: goldcoast | B26: Gold Coast, Australia | C26: Gold Coast | D26: Australia | E26: AU | F26: Oceania | G26: 🇦🇺 | H26: =TRUE() -> TRUE | I26: =TRUE() -> TRUE | J26: =FALSE() -> FALSE | K26: =FALSE() -> FALSE | L26: light | M26: 50 | N26: 46 | O26: 29 | P26: 0 | Q26: 0 | R26: 0 | S26: 0 | T26: 1 | U26: no_parks_with_hours|no_parks_with_coords|no_parks_with_url
A27: sydney | B27: Sydney | C27: Sydney | D27: Australia | E27: AU | F27: Oceania | G27: 🇦🇺 | H27: =TRUE() -> TRUE | I27: =FALSE() -> FALSE | J27: =FALSE() -> FALSE | K27: =FALSE() -> FALSE | L27: light | M27: 51 | N27: 32 | O27: 26 | P27: 0 | Q27: 0 | R27: 0 | S27: 0 | T27: 1 | U27: no_parks_with_hours|no_parks_with_coords|no_parks_with_url
A28: cruise | B28: Cruise Holiday | C28: Cruise | D28: At Sea | E28: XX | F28: Cruise | G28: 🚢 | H28: =TRUE() -> TRUE | I28: =TRUE() -> TRUE | J28: =FALSE() -> FALSE | K28: =FALSE() -> FALSE | L28: light | M28: 60 | N28: 54 | O28: 24 | P28: 0 | Q28: 0 | R28: 0 | S28: 0 | T28: 1 | U28: no_parks_with_hours|no_parks_with_coords|no_parks_with_url
A29: london | B29: London | C29: London | D29: United Kingdom | E29: GB | F29: Europe | G29: 🇬🇧 | H29: =TRUE() -> TRUE | I29: =TRUE() -> TRUE | J29: =FALSE() -> FALSE | K29: =FALSE() -> FALSE | L29: light | M29: 100 | N29: 73 | O29: 50 | P29: 0 | Q29: 0 | R29: 0 | S29: 0 | T29: 1 | U29: no_parks_with_hours|no_parks_with_coords|no_parks_with_url
A30: edinburgh | B30: Edinburgh & Scotland | C30: Edinburgh | D30: United Kingdom | E30: GB | F30: Europe | G30: 🏴󠁧󠁢󠁳󠁣󠁴󠁿 | H30: =TRUE() -> TRUE | I30: =TRUE() -> TRUE | J30: =FALSE() -> FALSE | K30: =FALSE() -> FALSE | L30: light | M30: 101 | N30: 71 | O30: 31 | P30: 0 | Q30: 0 | R30: 0 | S30: 0 | T30: 1 | U30: no_parks_with_hours|no_parks_with_coords|no_parks_with_url
A31: bath | B31: Bath & the Cotswolds | C31: Bath | D31: United Kingdom | E31: GB | F31: Europe | G31: 🇬🇧 | H31: =TRUE() -> TRUE | I31: =FALSE() -> FALSE | J31: =FALSE() -> FALSE | K31: =FALSE() -> FALSE | L31: light | M31: 102 | N31: 73 | O31: 30 | P31: 0 | Q31: 0 | R31: 0 | S31: 0 | T31: 1 | U31: no_parks_with_hours|no_parks_with_coords|no_parks_with_url
A32: liverpool | B32: Liverpool | C32: Liverpool | D32: United Kingdom | E32: GB | F32: Europe | G32: 🇬🇧 | H32: =TRUE() -> TRUE | I32: =FALSE() -> FALSE | J32: =FALSE() -> FALSE | K32: =FALSE() -> FALSE | L32: light | M32: 103 | N32: 49 | O32: 28 | P32: 0 | Q32: 0 | R32: 0 | S32: 0 | T32: 1 | U32: no_parks_with_hours|no_parks_with_coords|no_parks_with_url
A33: york | B33: York | C33: York | D33: United Kingdom | E33: GB | F33: Europe | G33: 🇬🇧 | H33: =TRUE() -> TRUE | I33: =FALSE() -> FALSE | J33: =FALSE() -> FALSE | K33: =FALSE() -> FALSE | L33: light | M33: 104 | N33: 64 | O33: 28 | P33: 0 | Q33: 0 | R33: 0 | S33: 0 | T33: 1 | U33: no_parks_with_hours|no_parks_with_coords|no_parks_with_url
A34: manchester | B34: Manchester | C34: Manchester | D34: United Kingdom | E34: GB | F34: Europe | G34: 🇬🇧 | H34: =TRUE() -> TRUE | I34: =FALSE() -> FALSE | J34: =FALSE() -> FALSE | K34: =FALSE() -> FALSE | L34: light | M34: 105 | N34: 56 | O34: 27 | P34: 0 | Q34: 0 | R34: 0 | S34: 0 | T34: 1 | U34: no_parks_with_hours|no_parks_with_coords|no_parks_with_url
A35: cambridge | B35: Cambridge & Oxford | C35: Cam/Ox | D35: United Kingdom | E35: GB | F35: Europe | G35: 🇬🇧 | H35: =TRUE() -> TRUE | I35: =FALSE() -> FALSE | J35: =FALSE() -> FALSE | K35: =FALSE() -> FALSE | L35: light | M35: 106 | N35: 60 | O35: 29 | P35: 0 | Q35: 0 | R35: 0 | S35: 0 | T35: 1 | U35: no_parks_with_hours|no_parks_with_coords|no_parks_with_url
A36: lakedist | B36: Lake District | C36: Lakes | D36: United Kingdom | E36: GB | F36: Europe | G36: 🇬🇧 | H36: =TRUE() -> TRUE | I36: =FALSE() -> FALSE | J36: =FALSE() -> FALSE | K36: =FALSE() -> FALSE | L36: light | M36: 107 | N36: 62 | O36: 27 | P36: 0 | Q36: 0 | R36: 0 | S36: 0 | T36: 1 | U36: no_parks_with_hours|no_parks_with_coords|no_parks_with_url
A37: cornwall | B37: Cornwall | C37: Cornwall | D37: United Kingdom | E37: GB | F37: Europe | G37: 🇬🇧 | H37: =TRUE() -> TRUE | I37: =FALSE() -> FALSE | J37: =FALSE() -> FALSE | K37: =FALSE() -> FALSE | L37: light | M37: 108 | N37: 49 | O37: 28 | P37: 0 | Q37: 0 | R37: 0 | S37: 0 | T37: 1 | U37: no_parks_with_hours|no_parks_with_coords|no_parks_with_url
A38: highlands | B38: Scottish Highlands | C38: Highlands | D38: United Kingdom | E38: GB | F38: Europe | G38: 🏴󠁧󠁢󠁳󠁣󠁴󠁿 | H38: =TRUE() -> TRUE | I38: =FALSE() -> FALSE | J38: =FALSE() -> FALSE | K38: =FALSE() -> FALSE | L38: light | M38: 109 | N38: 52 | O38: 27 | P38: 0 | Q38: 0 | R38: 0 | S38: 0 | T38: 1 | U38: no_parks_with_hours|no_parks_with_coords|no_parks_with_url
A39: cardiff | B39: Cardiff & Wales | C39: Cardiff | D39: United Kingdom | E39: GB | F39: Europe | G39: 🏴󠁧󠁢󠁷󠁬󠁳󠁿 | H39: =TRUE() -> TRUE | I39: =FALSE() -> FALSE | J39: =FALSE() -> FALSE | K39: =FALSE() -> FALSE | L39: light | M39: 110 | N39: 53 | O39: 27 | P39: 0 | Q39: 0 | R39: 0 | S39: 0 | T39: 1 | U39: no_parks_with_hours|no_parks_with_coords|no_parks_with_url
A40: belfast | B40: Belfast & Northern Ireland | C40: Belfast | D40: United Kingdom | E40: GB | F40: Europe | G40: 🇬🇧 | H40: =TRUE() -> TRUE | I40: =FALSE() -> FALSE | J40: =FALSE() -> FALSE | K40: =FALSE() -> FALSE | L40: light | M40: 111 | N40: 56 | O40: 27 | P40: 0 | Q40: 0 | R40: 0 | S40: 0 | T40: 1 | U40: no_parks_with_hours|no_parks_with_coords|no_parks_with_url
...

Sheet Parks
A1: id | B1: name | C1: icon | D1: park_group | E1: region_ids | F1: country | G1: latitude | H1: longitude | I1: official_url | J1: opens_at | K1: closes_at | L1: hours_known | M1: affiliate_hotel_query | N1: affiliate_ticket_url | O1: sort_order | P1: attractions_count | Q1: gaps
A2: romanba | B2: Roman Baths | D2: attractions | E2: bath|uk_combo | L2: false | O2: 840 | P2: 0 | Q2: no_icon|no_country|no_coords|no_official_url|no_hours
A3: bathabbey | B3: Bath Abbey | D3: sights | E3: bath|uk_combo | L3: false | O3: 841 | P3: 0 | Q3: no_icon|no_country|no_coords|no_official_url|no_hours
A4: royalcr | B4: Royal Crescent | D4: sights | E4: bath|uk_combo | L4: false | O4: 842 | P4: 0 | Q4: no_icon|no_country|no_coords|no_official_url|no_hours
A5: jasen | B5: Jane Austen Centre | D5: attractions | E5: bath|uk_combo | L5: false | O5: 843 | P5: 0 | Q5: no_icon|no_country|no_coords|no_official_url|no_hours
A6: thermae | B6: Thermae Bath Spa | D6: activities | E6: bath|uk_combo | L6: false | O6: 844 | P6: 0 | Q6: no_icon|no_country|no_coords|no_official_url|no_hours
A7: cots | B7: Cotswolds Villages | D7: sights | E7: bath|uk_combo | L7: false | O7: 845 | P7: 0 | Q7: no_icon|no_country|no_coords|no_official_url|no_hours
A8: castlec | B8: Castle Combe | D8: sights | E8: bath|uk_combo | L8: false | O8: 846 | P8: 0 | Q8: no_icon|no_country|no_coords|no_official_url|no_hours
A9: stoneh | B9: Stonehenge | D9: attractions | E9: bath|uk_combo | L9: false | O9: 847 | P9: 0 | Q9: no_icon|no_country|no_coords|no_official_url|no_hours
A10: titanic | B10: Titanic Belfast | D10: attractions | E10: belfast|uk_combo | L10: false | O10: 930 | P10: 0 | Q10: no_icon|no_country|no_coords|no_official_url|no_hours
A11: giants | B11: Giant's Causeway | D11: sights | E11: belfast|uk_combo | L11: false | O11: 931 | P11: 0 | Q11: no_icon|no_country|no_coords|no_official_url|no_hours
A12: gotour | B12: Game of Thrones Tour | D12: excursions | E12: belfast|uk_combo | L12: false | O12: 932 | P12: 0 | Q12: no_icon|no_country|no_coords|no_official_url|no_hours
A13: darkhed | B13: Dark Hedges | D13: sights | E13: belfast|uk_combo | L13: false | O13: 933 | P13: 0 | Q13: no_icon|no_country|no_coords|no_official_url|no_hours
... A199: ams | B199: Amsterdam Sights | D199: sights | E199: netherlands | L199: false | O199: 263 | P199: 0 | Q199: no_icon|no_country|no_coords|no_official_url|no_hours
A200: flyout | B200: Fly Out / Arrive | C200: ✈ | D200: travel | E200: orlando|cali|lasvegas|toronto|mexico|paris|uk|germany|spain|netherlands|denmark|italy|belgium|sweden|finland|tokyo|osaka|shanghai|hongkong|singapore|seoul|uae|goldcoast|sydney|cruise|custom|miami|florida_combo|london|edinburgh|bath|liverpool|york|manchester|cambridge|lakedist|cornwall|highlands|cardiff|belfast|brighton|stratfm|uk_combo | L200: false | O200: 1 | P200: 0 | Q200: no_country|no_coords|no_official_url|no_hours
A201: flyhome | B201: Fly Home / Depart | C201: ✈ | D201: travel | E201: orlando|cali|lasvegas|toronto|mexico|paris|uk|germany|spain|netherlands|denmark|italy|belgium|sweden|finland|tokyo|osaka|shanghai|hongkong|singapore|seoul|uae|goldcoast|sydney|cruise|custom|miami|florida_combo|london|edinburgh|bath|liverpool|york|manchester|cambridge|lakedist|cornwall|highlands|cardiff|belfast|brighton|stratfm|uk_combo | L201: false | O201: 2 | P201: 0 | Q201: no_country|no_coords|no_official_url|no_hours
A202: embark | B202: Cruise Embark | C202: ⚓ | D202: travel | E202: orlando|cali|lasvegas|toronto|mexico|paris|uk|germany|spain|netherlands|denmark|italy|belgium|sweden|finland|tokyo|osaka|shanghai|hongkong|singapore|seoul|uae|goldcoast|sydney|cruise|custom|miami|florida_combo|london|edinburgh|bath|liverpool|york|manchester|cambridge|lakedist|cornwall|highlands|cardiff|belfast|brighton|stratfm|uk_combo | L202: false | O202: 3 | P202: 0 | Q202: no_country|no_coords|no_official_url|no_hours
A203: disemb | B203: Cruise Disembark | C203: ⚓ | D203: travel | E203: orlando|cali|lasvegas|toronto|mexico|paris|uk|germany|spain|netherlands|denmark|italy|belgium|sweden|finland|tokyo|osaka|shanghai|hongkong|singapore|seoul|uae|goldcoast|sydney|cruise|custom|miami|florida_combo|london|edinburgh|bath|liverpool|york|manchester|cambridge|lakedist|cornwall|highlands|cardiff|belfast|brighton|stratfm|uk_combo | L203: false | O203: 4 | P203: 0 | Q203: no_country|no_coords|no_official_url|no_hours
A204: sea | B204: Cruise — At Sea | C204: ⚓ | D204: travel | E204: orlando|cali|lasvegas|toronto|mexico|paris|uk|germany|spain|netherlands|denmark|italy|belgium|sweden|finland|tokyo|osaka|shanghai|hongkong|singapore|seoul|uae|goldcoast|sydney|cruise|custom|miami|florida_combo|london|edinburgh|bath|liverpool|york|manchester|cambridge|lakedist|cornwall|highlands|cardiff|belfast|brighton|stratfm|uk_combo | L204: false | O204: 5 | P204: 0 | Q204: no_country|no_coords|no_official_url|no_hours
A205: port | B205: Cruise — Port Day | C205: ⚓ | D205: travel | E205: orlando|cali|lasvegas|toronto|mexico|paris|uk|germany|spain|netherlands|denmark|italy|belgium|sweden|finland|tokyo|osaka|shanghai|hongkong|singapore|seoul|uae|goldcoast|sydney|cruise|custom|miami|florida_combo|london|edinburgh|bath|liverpool|york|manchester|cambridge|lakedist|cornwall|highlands|cardiff|belfast|brighton|stratfm|uk_combo | L205: false | O205: 6 | P205: 0 | Q205: no_country|no_coords|no_official_url|no_hours
A206: exc | B206: Shore Excursion | C206: ⚓ | D206: excursions | E206: orlando|cali|lasvegas|toronto|mexico|paris|uk|germany|spain|netherlands|denmark|italy|belgium|sweden|finland|tokyo|osaka|shanghai|hongkong|singapore|seoul|uae|goldcoast|sydney|cruise|custom|miami|florida_combo|london|edinburgh|bath|liverpool|york|manchester|cambridge|lakedist|cornwall|highlands|cardiff|belfast|brighton|stratfm|uk_combo | L206: false | O206: 150 | P206: 0 | Q206: no_country|no_coords|no_official_url|no_hours
A207: beach | B207: Beach Day | D207: excursions | E207: orlando|cali|lasvegas|toronto|mexico|paris|uk|germany|spain|netherlands|denmark|italy|belgium|sweden|finland|tokyo|osaka|shanghai|hongkong|singapore|seoul|uae|goldcoast|sydney|cruise|custom|miami|florida_combo|london|edinburgh|bath|liverpool|york|manchester|cambridge|lakedist|cornwall|highlands|cardiff|belfast|brighton|stratfm|uk_combo | L207: false | O207: 151 | P207: 0 | Q207: no_icon|no_country|no_coords|no_official_url|no_hours
A208: snk | B208: Snorkel / Dive | D208: excursions | E208: orlando|cali|lasvegas|toronto|mexico|paris|uk|germany|spain|netherlands|denmark|italy|belgium|sweden|finland|tokyo|osaka|shanghai|hongkong|singapore|seoul|uae|goldcoast|sydney|cruise|custom|miami|florida_combo|london|edinburgh|bath|liverpool|york|manchester|cambridge|lakedist|cornwall|highlands|cardiff|belfast|brighton|stratfm|uk_combo | L208: false | O208: 152 | P208: 0 | Q208: no_icon|no_country|no_coords|no_official_url|no_hours
A209: psh | B209: Port Shopping | D209: excursions | E209: orlando|cali|lasvegas|toronto|mexico|paris|uk|germany|spain|netherlands|denmark|italy|belgium|sweden|finland|tokyo|osaka|shanghai|hongkong|singapore|seoul|uae|goldcoast|sydney|cruise|custom|miami|florida_combo|london|edinburgh|bath|liverpool|york|manchester|cambridge|lakedist|cornwall|highlands|cardiff|belfast|brighton|stratfm|uk_combo | L209: false | O209: 153 | P209: 0 | Q209: no_icon|no_country|no_coords|no_official_url|no_hours
A210: ship | B210: Ship Day | C210: ⚓ | D210: excursions | E210: orlando|cali|lasvegas|toronto|mexico|paris|uk|germany|spain|netherlands|denmark|italy|belgium|sweden|finland|tokyo|osaka|shanghai|hongkong|singapore|seoul|uae|goldcoast|sydney|cruise|custom|miami|florida_combo|london|edinburgh|bath|liverpool|york|manchester|cambridge|lakedist|cornwall|highlands|cardiff|belfast|brighton|stratfm|uk_combo | L210: false | O210: 154 | P210: 0 | Q210: no_country|no_coords|no_official_url|no_hours
A211: pool | B211: Ship Pool / Bar | D211: excursions | E211: orlando|cali|lasvegas|toronto|mexico|paris|uk|germany|spain|netherlands|denmark|italy|belgium|sweden|finland|tokyo|osaka|shanghai|hongkong|singapore|seoul|uae|goldcoast|sydney|cruise|custom|miami|florida_combo|london|edinburgh|bath|liverpool|york|manchester|cambridge|lakedist|cornwall|highlands|cardiff|belfast|brighton|stratfm|uk_combo | L211: false | O211: 155 | P211: 0 | Q211: no_icon|no_country|no_coords|no_official_url|no_hours
A212: spac | B212: Ship Spa | D212: excursions | E212: orlando|cali|lasvegas|toronto|mexico|paris|uk|germany|spain|netherlands|denmark|italy|belgium|sweden|finland|tokyo|osaka|shanghai|hongkong|singapore|seoul|uae|goldcoast|sydney|cruise|custom|miami|florida_combo|london|edinburgh|bath|liverpool|york|manchester|cambridge|lakedist|cornwall|highlands|cardiff|belfast|brighton|stratfm|uk_combo | L212: false | O212: 156 | P212: 0 | Q212: no_icon|no_country|no_coords|no_official_url|no_hours
A213: owl | B213: Quick Service | D213: dining | E213: orlando|cali|lasvegas|toronto|mexico|paris|uk|germany|spain|netherlands|denmark|italy|belgium|sweden|finland|tokyo|osaka|shanghai|hongkong|singapore|seoul|uae|goldcoast|sydney|cruise|custom|miami|florida_combo|london|edinburgh|bath|liverpool|york|manchester|cambridge|lakedist|cornwall|highlands|cardiff|belfast|brighton|stratfm|uk_combo | L213: false | O213: 160 | P213: 0 | Q213: no_icon|no_country|no_coords|no_official_url|no_hours
A214: tsr | B214: Table Service | D214: dining | E214: orlando|cali|lasvegas|toronto|mexico|paris|uk|germany|spain|netherlands|denmark|italy|belgium|sweden|finland|tokyo|osaka|shanghai|hongkong|singapore|seoul|uae|goldcoast|sydney|cruise|custom|miami|florida_combo|london|edinburgh|bath|liverpool|york|manchester|cambridge|lakedist|cornwall|highlands|cardiff|belfast|brighton|stratfm|uk_combo | L214: false | O214: 161 | P214: 0 | Q214: no_icon|no_country|no_coords|no_official_url|no_hours
A215: char | B215: Character Dining | D215: dining | E215: orlando|cali|lasvegas|toronto|mexico|paris|uk|germany|spain|netherlands|denmark|italy|belgium|sweden|finland|tokyo|osaka|shanghai|hongkong|singapore|seoul|uae|goldcoast|sydney|cruise|custom|miami|florida_combo|london|edinburgh|bath|liverpool|york|manchester|cambridge|lakedist|cornwall|highlands|cardiff|belfast|brighton|stratfm|uk_combo | L215: false | O215: 162 | P215: 0 | Q215: no_icon|no_country|no_coords|no_official_url|no_hours
A216: villa | B216: Villa / Home Cook | D216: dining | E216: orlando|cali|lasvegas|toronto|mexico|paris|uk|germany|spain|netherlands|denmark|italy|belgium|sweden|finland|tokyo|osaka|shanghai|hongkong|singapore|seoul|uae|goldcoast|sydney|cruise|custom|miami|florida_combo|london|edinburgh|bath|liverpool|york|manchester|cambridge|lakedist|cornwall|highlands|cardiff|belfast|brighton|stratfm|uk_combo | L216: false | O216: 163 | P216: 0 | Q216: no_icon|no_country|no_coords|no_official_url|no_hours
A217: specd | B217: Specialty Dining | D217: dining | E217: orlando|cali|lasvegas|toronto|mexico|paris|uk|germany|spain|netherlands|denmark|italy|belgium|sweden|finland|tokyo|osaka|shanghai|hongkong|singapore|seoul|uae|goldcoast|sydney|cruise|custom|miami|florida_combo|london|edinburgh|bath|liverpool|york|manchester|cambridge|lakedist|cornwall|highlands|cardiff|belfast|brighton|stratfm|uk_combo | L217: false | O217: 164 | P217: 0 | Q217: no_icon|no_country|no_coords|no_official_url|no_hours
A218: rest | B218: Rest / Pool | D218: activities | E218: orlando|cali|lasvegas|toronto|mexico|paris|uk|germany|spain|netherlands|denmark|italy|belgium|sweden|finland|tokyo|osaka|shanghai|hongkong|singapore|seoul|uae|goldcoast|sydney|cruise|custom|miami|florida_combo|london|edinburgh|bath|liverpool|york|manchester|cambridge|lakedist|cornwall|highlands|cardiff|belfast|brighton|stratfm|uk_combo | L218: false | O218: 170 | P218: 0 | Q218: no_icon|no_country|no_coords|no_official_url|no_hours
A219: shop | B219: Shopping / Outlets | D219: activities | E219: orlando|cali|lasvegas|toronto|mexico|paris|uk|germany|spain|netherlands|denmark|italy|belgium|sweden|finland|tokyo|osaka|shanghai|hongkong|singapore|seoul|uae|goldcoast|sydney|cruise|custom|miami|florida_combo|london|edinburgh|bath|liverpool|york|manchester|cambridge|lakedist|cornwall|highlands|cardiff|belfast|brighton|stratfm|uk_combo | L219: false | O219: 171 | P219: 0 | Q219: no_icon|no_country|no_coords|no_official_url|no_hours
A220: golf | B220: Golf | D220: activities | E220: orlando|cali|lasvegas|toronto|mexico|paris|uk|germany|spain|netherlands|denmark|italy|belgium|sweden|finland|tokyo|osaka|shanghai|hongkong|singapore|seoul|uae|goldcoast|sydney|cruise|custom|miami|florida_combo|london|edinburgh|bath|liverpool|york|manchester|cambridge|lakedist|cornwall|highlands|cardiff|belfast|brighton|stratfm|uk_combo | L220: false | O220: 172 | P220: 0 | Q220: no_icon|no_country|no_coords|no_official_url|no_hours
A221: spa | B221: Spa / Villa Day | D221: activities | E221: orlando|cali|lasvegas|toronto|mexico|paris|uk|germany|spain|netherlands|denmark|italy|belgium|sweden|finland|tokyo|osaka|shanghai|hongkong|singapore|seoul|uae|goldcoast|sydney|cruise|custom|miami|florida_combo|london|edinburgh|bath|liverpool|york|manchester|cambridge|lakedist|cornwall|highlands|cardiff|belfast|brighton|stratfm|uk_combo | L221: false | O221: 173 | P221: 0 | Q221: no_icon|no_country|no_coords|no_official_url|no_hours
A222: mk | B222: Magic Kingdom | D222: disney | E222: orlando|florida_combo | L222: false | O222: 10 | P222: 13 | Q222: no_icon|no_country|no_coords|no_official_url|no_hours
... A352: yorkwall | B352: York City Walls | D352: sights | E352: york|uk_combo | L352: false | O352: 865 | P352: 0 | Q352: no_icon|no_country|no_coords|no_official_url|no_hours

Sheet Attractions
A1: id | B1: park_id | C1: park_name | D1: region_ids | E1: name | F1: category | G1: thrill_level | H1: is_indoor | I1: duration_minutes | J1: height_requirement_cm | K1: skip_line_system | L1: skip_line_tier | M1: avg_wait_peak_minutes | N1: avg_wait_offpeak_minutes | O1: is_seasonal | P1: is_temporarily_closed | Q1: tags | R1: official_url | S1: sort_order | T1: gaps
A2: dca-goofys-sky | B2: dca | C2: California Adventure | D2: cali | E2: Goofy's Sky School | F2: ride | G2: moderate | H2: false | J2: 107 | M2: 30 | O2: false | P2: false | S2: 0 | T2: no_duration|no_offpeak_wait|no_skip_line_system|no_tags|no_official_url
A3: dca-grizzly | B3: dca | C3: California Adventure | D3: cali | E3: Grizzly River Run | F3: ride | G3: moderate | H3: false | J3: 107 | K3: lightning_lane | L3: multi_pass | M3: 35 | O3: false | P3: false | S3: 0 | T3: no_duration|no_offpeak_wait|no_tags|no_official_url
A4: dca-guardians | B4: dca | C4: California Adventure | D4: cali | E4: Guardians of the Galaxy: Mission BREAKOUT! | F4: ride | G4: intense | H4: false | J4: 102 | K4: lightning_lane | L4: multi_pass | M4: 55 | O4: false | P4: false | S4: 0 | T4: no_duration|no_offpeak_wait|no_tags|no_official_url
A5: dca-incredicoaster | B5: dca | C5: California Adventure | D5: cali | E5: Incredicoaster | F5: ride | G5: intense | H5: false | J5: 122 | K5: lightning_lane | L5: multi_pass | M5: 50 | O5: false | P5: false | S5: 0 | T5: no_duration|no_offpeak_wait|no_tags|no_official_url
A6: dca-rsr | B6: dca | C6: California Adventure | D6: cali | E6: Radiator Springs Racers | F6: ride | G6: moderate | H6: false | J6: 102 | K6: lightning_lane | L6: single_pass | M6: 80 | O6: false | P6: false | S6: 0 | T6: no_duration|no_offpeak_wait|no_tags|no_official_url
A7: dca-soarin | B7: dca | C7: California Adventure | D7: cali | E7: Soarin' Around the World | F7: ride | G7: gentle | H7: false | J7: 102 | K7: lightning_lane | L7: multi_pass | M7: 45 | O7: false | P7: false | S7: 0 | T7: no_duration|no_offpeak_wait|no_tags|no_official_url
A8: dca-toy-story | B8: dca | C8: California Adventure | D8: cali | E8: Toy Story Midway Mania! | F8: ride | G8: gentle | H8: false | K8: lightning_lane | L8: multi_pass | M8: 50 | O8: false | P8: false | S8: 0 | T8: no_duration|no_offpeak_wait|no_tags|no_official_url
A9: dca-web-slingers | B9: dca | C9: California Adventure | D9: cali | E9: WEB SLINGERS: A Spider-Man Adventure | F9: ride | G9: gentle | H9: false | K9: lightning_lane | L9: multi_pass | M9: 60 | O9: false | P9: false | S9: 0 | T9: no_duration|no_offpeak_wait|no_tags|no_official_url
A10: dl-big-thunder | B10: dl | C10: Disneyland Park | D10: cali | E10: Big Thunder Mountain Railroad | F10: ride | G10: moderate | H10: false | J10: 102 | K10: lightning_lane | L10: multi_pass | M10: 50 | O10: false | P10: false | S10: 0 | T10: no_duration|no_offpeak_wait|no_tags|no_official_url
A11: dl-haunted-mansion | B11: dl | C11: Disneyland Park | D11: cali | E11: Haunted Mansion | F11: ride | G11: gentle | H11: false | K11: lightning_lane | L11: multi_pass | M11: 35 | O11: false | P11: false | S11: 0 | T11: no_duration|no_offpeak_wait|no_tags|no_official_url
A12: dl-indiana-jones | B12: dl | C12: Disneyland Park | D12: cali | E12: Indiana Jones Adventure | F12: ride | G12: thrilling | H12: false | J12: 117 | K12: lightning_lane | L12: multi_pass | M12: 55 | O12: false | P12: false | S12: 0 | T12: no_duration|no_offpeak_wait|no_tags|no_official_url
A13: dl-small-world | B13: dl | C13: Disneyland Park | D13: cali | E13: it's a small world | F13: ride | G13: gentle | H13: false | K13: lightning_lane | L13: multi_pass | M13: 25 | O13: false | P13: false | S13: 0 | T13: no_duration|no_offpeak_wait|no_tags|no_official_url
A14: dl-matterhorn | B14: dl | C14: Disneyland Park | D14: cali | E14: Matterhorn Bobsleds | F14: ride | G14: moderate | H14: false | J14: 107 | K14: lightning_lane | L14: multi_pass | M14: 45 | O14: false | P14: false | S14: 0 | T14: no_duration|no_offpeak_wait|no_tags|no_official_url
A15: dl-smugglers-run | B15: dl | C15: Disneyland Park | D15: cali | E15: Millennium Falcon: Smugglers Run | F15: ride | G15: moderate | H15: false | J15: 97 | K15: lightning_lane | L15: multi_pass | M15: 50 | O15: false | P15: false | S15: 0 | T15: no_duration|no_offpeak_wait|no_tags|no_official_url
A16: dl-peter-pan | B16: dl | C16: Disneyland Park | D16: cali | E16: Peter Pan's Flight | F16: ride | G16: gentle | H16: false | K16: lightning_lane | L16: multi_pass | M16: 60 | O16: false | P16: false | S16: 0 | T16: no_duration|no_offpeak_wait|no_tags|no_official_url
A17: dl-pirates | B17: dl | C17: Disneyland Park | D17: cali | E17: Pirates of the Caribbean | F17: ride | G17: gentle | H17: false | M17: 30 | O17: false | P17: false | S17: 0 | T17: no_duration|no_offpeak_wait|no_skip_line_system|no_tags|no_official_url
A18: dl-space-mountain | B18: dl | C18: Disneyland Park | D18: cali | E18: Space Mountain | F18: ride | G18: thrilling | H18: false | J18: 102 | K18: lightning_lane | L18: multi_pass | M18: 60 | O18: false | P18: false | S18: 0 | T18: no_duration|no_offpeak_wait|no_tags|no_official_url
A19: dl-rise-resistance | B19: dl | C19: Disneyland Park | D19: cali | E19: Star Wars: Rise of the Resistance | F19: ride | G19: thrilling | H19: false | J19: 102 | K19: lightning_lane | L19: single_pass | M19: 90 | O19: false | P19: false | S19: 0 | T19: no_duration|no_offpeak_wait|no_tags|no_official_url
A20: hkdl-ant-man | B20: hkdl | C20: Hong Kong Disneyland | D20: hongkong | E20: Ant-Man and The Wasp: Nano Battle! | F20: ride | G20: gentle | H20: false | M20: 25 | O20: false | P20: false | S20: 0 | T20: no_duration|no_offpeak_wait|no_skip_line_system|no_tags|no_official_url
A21: hkdl-grizzly-mountain | B21: hkdl | C21: Hong Kong Disneyland | D21: hongkong | E21: Big Grizzly Mountain Runaway Mine Cars | F21: ride | G21: thrilling | H21: false | J21: 102 | M21: 35 | O21: false | P21: false | S21: 0 | T21: no_duration|no_offpeak_wait|no_skip_line_system|no_tags|no_official_url
A22: hkdl-frozen-ever-after | B22: hkdl | C22: Hong Kong Disneyland | D22: hongkong | E22: Frozen Ever After | F22: ride | G22: gentle | H22: false | M22: 60 | O22: false | P22: false | S22: 0 | T22: no_duration|no_offpeak_wait|no_skip_line_system|no_tags|no_official_url
A23: hkdl-space-mountain | B23: hkdl | C23: Hong Kong Disneyland | D23: hongkong | E23: Hyperspace Mountain | F23: ride | G23: thrilling | H23: false | J23: 102 | M23: 40 | O23: false | P23: false | S23: 0 | T23: no_duration|no_offpeak_wait|no_skip_line_system|no_tags|no_official_url
A24: hkdl-iron-man | B24: hkdl | C24: Hong Kong Disneyland | D24: hongkong | E24: Iron Man Experience | F24: ride | G24: thrilling | H24: false | J24: 102 | M24: 30 | O24: false | P24: false | S24: 0 | T24: no_duration|no_offpeak_wait|no_skip_line_system|no_tags|no_official_url
A25: hkdl-mystic-manor | B25: hkdl | C25: Hong Kong Disneyland | D25: hongkong | E25: Mystic Manor | F25: ride | G25: gentle | H25: false | M25: 30 | O25: false | P25: false | S25: 0 | T25: no_duration|no_offpeak_wait|no_skip_line_system|no_tags|no_official_url
A26: hkdl-frozen-coaster | B26: hkdl | C26: Hong Kong Disneyland | D26: hongkong | E26: Wandering Oaken's Sliding Sleighs | F26: ride | G26: moderate | H26: false | J26: 102 | M26: 50 | O26: false | P26: false | S26: 0 | T26: no_duration|no_offpeak_wait|no_skip_line_system|no_tags|no_official_url
A27: ak-flight-of-passage | B27: ak | C27: Animal Kingdom | D27: orlando|florida_combo | E27: Avatar Flight of Passage | F27: ride | G27: intense | H27: true | I27: 5 | J27: 112 | K27: disney_lightning_lane | L27: single_pass | M27: 85 | N27: 40 | O27: false | P27: false | Q27: simulator|thrilling | S27: 10 | T27: no_official_url
A28: ak-expedition-everest | B28: ak | C28: Animal Kingdom | D28: orlando|florida_combo | E28: Expedition Everest | F28: ride | G28: thrilling | H28: false | I28: 3 | J28: 112 | K28: disney_lightning_lane | L28: multi_pass_tier2 | M28: 45 | N28: 15 | O28: false | P28: false | Q28: roller_coaster|thrilling | S28: 20 | T28: no_official_url
A29: ak-kilimanjaro-safaris | B29: ak | C29: Animal Kingdom | D29: orlando|florida_combo | E29: Kilimanjaro Safaris | F29: ride | G29: gentle | H29: false | I29: 22 | K29: disney_lightning_lane | L29: multi_pass_tier2 | M29: 50 | N29: 20 | O29: false | P29: false | Q29: family|outdoor|safari | S29: 30 | T29: no_official_url
A30: ak-navi-river | B30: ak | C30: Animal Kingdom | D30: orlando|florida_combo | E30: Na'vi River Journey | F30: ride | G30: gentle | H30: true | I30: 5 | K30: disney_lightning_lane | L30: multi_pass_tier2 | M30: 55 | N30: 20 | O30: false | P30: false | Q30: dark_ride|family|boat_ride | S30: 40 | T30: no_official_url
A31: ak-kali-river | B31: ak | C31: Animal Kingdom | D31: orlando|florida_combo | E31: Kali River Rapids | F31: ride | G31: moderate | H31: false | I31: 5 | J31: 97 | K31: disney_lightning_lane | L31: multi_pass_tier2 | M31: 30 | N31: 10 | O31: false | P31: false | Q31: water_ride|family | S31: 50 | T31: no_official_url
A32: ak-dinosaur | B32: ak | C32: Animal Kingdom | D32: orlando|florida_combo | E32: DINOSAUR | F32: ride | G32: thrilling | H32: true | I32: 4 | J32: 102 | K32: disney_lightning_lane | L32: multi_pass_tier2 | M32: 30 | N32: 10 | O32: false | P32: true | Q32: dark_ride|thrilling | S32: 60 | T32: no_official_url
A33: ep-guardians-galaxy | B33: ep | C33: EPCOT | D33: orlando|florida_combo | E33: Guardians of the Galaxy: Cosmic Rewind | F33: ride | G33: intense | H33: true | I33: 3 | J33: 107 | K33: disney_lightning_lane | L33: single_pass | M33: 85 | N33: 40 | O33: false | P33: false | Q33: roller_coaster|thrilling|dark_ride | S33: 10 | T33: no_official_url
A34: ep-frozen-ever-after | B34: ep | C34: EPCOT | D34: orlando|florida_combo | E34: Frozen Ever After | F34: ride | G34: gentle | H34: true | I34: 5 | K34: disney_lightning_lane | L34: multi_pass_tier1 | M34: 60 | N34: 25 | O34: false | P34: false | Q34: dark_ride|family|boat_ride | S34: 20 | T34: no_official_url
A35: ep-remys-ratatouille | B35: ep | C35: EPCOT | D35: orlando|florida_combo | E35: Remy's Ratatouille Adventure | F35: ride | G35: gentle | H35: true | I35: 5 | K35: disney_lightning_lane | L35: multi_pass_tier1 | M35: 55 | N35: 20 | O35: false | P35: false | Q35: dark_ride|family|trackless | S35: 30 | T35: no_official_url
A36: ep-test-track | B36: ep | C36: EPCOT | D36: orlando|florida_combo | E36: Test Track | F36: ride | G36: thrilling | H36: false | I36: 5 | J36: 102 | K36: disney_lightning_lane | L36: multi_pass_tier1 | M36: 65 | N36: 30 | O36: false | P36: false | Q36: thrilling|interactive | S36: 40 | T36: no_official_url
A37: ep-soarin | B37: ep | C37: EPCOT | D37: orlando|florida_combo | E37: Soarin' Around the World | F37: ride | G37: moderate | H37: true | I37: 5 | J37: 102 | K37: disney_lightning_lane | L37: multi_pass_tier2 | M37: 45 | N37: 20 | O37: false | P37: false | Q37: family|simulator | S37: 50 | T37: no_official_url
A38: ep-mission-space | B38: ep | C38: EPCOT | D38: orlando|florida_combo | E38: Mission: SPACE | F38: ride | G38: intense | H38: true | I38: 5 | J38: 112 | K38: disney_lightning_lane | L38: multi_pass_tier2 | M38: 30 | N38: 10 | O38: false | P38: false | Q38: simulator|thrilling | S38: 60 | T38: no_official_url
A39: ep-spaceship-earth | B39: ep | C39: EPCOT | D39: orlando|florida_combo | E39: Spaceship Earth | F39: ride | G39: gentle | H39: true | I39: 15 | K39: disney_lightning_lane | L39: multi_pass_tier2 | M39: 25 | N39: 10 | O39: false | P39: false | Q39: dark_ride|family|classic | S39: 70 | T39: no_official_url
A40: ep-living-with-land | B40: ep | C40: EPCOT | D40: orlando|florida_combo | E40: Living with the Land | F40: ride | G40: gentle | H40: true | I40: 14 | K40: disney_lightning_lane | L40: multi_pass_tier2 | M40: 20 | N40: 10 | O40: false | P40: false | Q40: family|boat_ride|educational | S40: 80 | T40: no_official_url
...

Sheet Skip-Line Map
A1: region_id | B1: skip_line_system_id
A2: bath | B2: none
A3: belfast | B3: none
A4: belgium | B4: none
A5: brighton | B5: none
A6: cali | B6: lightning_lane
A7: cali | B7: universal_express
A8: cambridge | B8: none
A9: cardiff | B9: none
A10: cornwall | B10: none
A11: cruise | B11: none
A12: custom | B12: none
... A47: york | B47: none

Sheet Gap Analysis
A1: Gap Analysis
A2: Counts per gap flag — formulas, will update if data sheets change
A4: Regions — parity_gaps column (col U)
A5: Flag | B5: Count | C5: % of regions
A6: description_too_short | B6: =COUNTIF(Regions!U2:U1000,"*description_too_short*") -> 0 | C6: =IFERROR(B6/COUNTA(Regions!A2:A1000),0) -> 0
A7: no_skip_line_systems | B7: =COUNTIF(Regions!U2:U1000,"*no_skip_line_systems*") -> 0 | C7: =IFERROR(B7/COUNTA(Regions!A2:A1000),0) -> 0
A8: tier_overstated_no_attractions | B8: =COUNTIF(Regions!U2:U1000,"*tier_overstated_no_attractions*") -> 4 | C8: =IFERROR(B8/COUNTA(Regions!A2:A1000),0) -> 0.093023256
A9: no_parks_with_hours | B9: =COUNTIF(Regions!U2:U1000,"*no_parks_with_hours*") -> 43 | C9: =IFERROR(B9/COUNTA(Regions!A2:A1000),0) -> 1
A10: no_parks_with_coords | B10: =COUNTIF(Regions!U2:U1000,"*no_parks_with_coords*") -> 43 | C10: =IFERROR(B10/COUNTA(Regions!A2:A1000),0) -> 1
A11: no_parks_with_url | B11: =COUNTIF(Regions!U2:U1000,"*no_parks_with_url*") -> 43 | C11: =IFERROR(B11/COUNTA(Regions!A2:A1000),0) -> 1
A14: Parks — gaps column (col Q)
A15: Flag | B15: Count | C15: % of parks
A16: no_icon | B16: =COUNTIF(Parks!Q2:Q1000,"*no_icon*") -> 343 | C16: =IFERROR(B16/COUNTA(Parks!A2:A1000),0) -> 0.97720798
A17: no_country | B17: =COUNTIF(Parks!Q2:Q1000,"*no_country*") -> 351 | C17: =IFERROR(B17/COUNTA(Parks!A2:A1000),0) -> 1
A18: no_coords | B18: =COUNTIF(Parks!Q2:Q1000,"*no_coords*") -> 351 | C18: =IFERROR(B18/COUNTA(Parks!A2:A1000),0) -> 1
A19: no_official_url | B19: =COUNTIF(Parks!Q2:Q1000,"*no_official_url*") -> 351 | C19: =IFERROR(B19/COUNTA(Parks!A2:A1000),0) -> 1
A20: no_hours | B20: =COUNTIF(Parks!Q2:Q1000,"*no_hours*") -> 351 | C20: =IFERROR(B20/COUNTA(Parks!A2:A1000),0) -> 1
A21: theme_park_no_attractions | B21: =COUNTIF(Parks!Q2:Q1000,"*theme_park_no_attractions*") -> 23 | C21: =IFERROR(B21/COUNTA(Parks!A2:A1000),0) -> 0.065527066
A24: Attractions — gaps column (col T)
A25: Flag | B25: Count | C25: % of attractions
A26: no_duration | B26: =COUNTIF(Attractions!T2:T1000,"*no_duration*") -> 40 | C26: =IFERROR(B26/COUNTA(Attractions!A2:A1000),0) -> 0.4
A27: no_peak_wait | B27: =COUNTIF(Attractions!T2:T1000,"*no_peak_wait*") -> 0 | C27: =IFERROR(B27/COUNTA(Attractions!A2:A1000),0) -> 0
A28: no_offpeak_wait | B28: =COUNTIF(Attractions!T2:T1000,"*no_offpeak_wait*") -> 40 | C28: =IFERROR(B28/COUNTA(Attractions!A2:A1000),0) -> 0.4
A29: no_skip_line_system | B29: =COUNTIF(Attractions!T2:T1000,"*no_skip_line_system*") -> 14 | C29: =IFERROR(B29/COUNTA(Attractions!A2:A1000),0) -> 0.14
A30: no_tags | B30: =COUNTIF(Attractions!T2:T1000,"*no_tags*") -> 40 | C30: =IFERROR(B30/COUNTA(Attractions!A2:A1000),0) -> 0.4
A31: no_official_url | B31: =COUNTIF(Attractions!T2:T1000,"*no_official_url*") -> 100 | C31: =IFERROR(B31/COUNTA(Attractions!A2:A1000),0) -> 1
